2025-08-05 20:33:38,368 - logic - INFO - Attempting to load symptom checker resources...
2025-08-05 20:33:38,369 - logic - WARNING - Cleaned data file 'data/cleaned_diseases.csv' not found. Attempting to clean original data from 'data/diseases.csv'.
2025-08-05 20:33:38,369 - data_utils - INFO - Starting advanced data cleaning from 'data/diseases.csv' to 'data/cleaned_diseases.csv'...
2025-08-05 20:33:38,381 - data_utils - ERROR - An error occurred during advanced data cleaning: Error tokenizing data. C error: Expected 3 fields in line 66, saw 5
Traceback (most recent call last):
  File "C:\Users\Admin\Documents\GitHub\idk-wut\data_utils.py", line 112, in clean_disease_data
    df = pd.read_csv(input_csv_path)
         ^^^^^^^^^^^^^^^^^^^^^^^^^^^
  File "C:\Users\Admin\AppData\Local\Packages\PythonSoftwareFoundation.Python.3.11_qbz5n2kfra8p0\LocalCache\local-packages\Python311\site-packages\pandas\io\parsers\readers.py", line 1026, in read_csv
    return _read(filepath_or_buffer, kwds)
           ^^^^^^^^^^^^^^^^^^^^^^^^^^^^^^^
  File "C:\Users\Admin\AppData\Local\Packages\PythonSoftwareFoundation.Python.3.11_qbz5n2kfra8p0\LocalCache\local-packages\Python311\site-packages\pandas\io\parsers\readers.py", line 626, in _read
    return parser.read(nrows)
           ^^^^^^^^^^^^^^^^^^
  File "C:\Users\Admin\AppData\Local\Packages\PythonSoftwareFoundation.Python.3.11_qbz5n2kfra8p0\LocalCache\local-packages\Python311\site-packages\pandas\io\parsers\readers.py", line 1923, in read
    ) = self._engine.read(  # type: ignore[attr-defined]
        ^^^^^^^^^^^^^^^^^^^^^^^^^^^^^^^^^^^^^^^^^^^^^^^^
  File "C:\Users\Admin\AppData\Local\Packages\PythonSoftwareFoundation.Python.3.11_qbz5n2kfra8p0\LocalCache\local-packages\Python311\site-packages\pandas\io\parsers\c_parser_wrapper.py", line 234, in read
    chunks = self._reader.read_low_memory(nrows)
             ^^^^^^^^^^^^^^^^^^^^^^^^^^^^^^^^^^^
  File "pandas/_libs/parsers.pyx", line 838, in pandas._libs.parsers.TextReader.read_low_memory
  File "pandas/_libs/parsers.pyx", line 905, in pandas._libs.parsers.TextReader._read_rows
  File "pandas/_libs/parsers.pyx", line 874, in pandas._libs.parsers.TextReader._tokenize_rows
  File "pandas/_libs/parsers.pyx", line 891, in pandas._libs.parsers.TextReader._check_tokenize_status
  File "pandas/_libs/parsers.pyx", line 2061, in pandas._libs.parsers.raise_parser_error
pandas.errors.ParserError: Error tokenizing data. C error: Expected 3 fields in line 66, saw 5

2025-08-05 20:33:38,385 - logic - ERROR - Failed to clean data. Cannot proceed with loading resources.
2025-08-05 20:33:38,385 - app - ERROR - Failed to initialize SymptomChecker: Failed to initialize SymptomChecker resources. Please check logs.
2025-08-05 20:51:10,130 - logic - INFO - Attempting to load symptom checker resources...
2025-08-05 20:51:10,131 - logic - WARNING - Cleaned data file 'data/cleaned_diseases.csv' not found. Attempting to clean original data from 'data/diseases.csv'.
2025-08-05 20:51:10,131 - data_utils - INFO - Starting advanced data cleaning from 'data/diseases.csv' to 'data/cleaned_diseases.csv'...
2025-08-05 20:51:10,133 - data_utils - ERROR - An error occurred during advanced data cleaning: Error tokenizing data. C error: Expected 3 fields in line 66, saw 5
Traceback (most recent call last):
  File "C:\Users\Admin\Documents\GitHub\idk-wut\data_utils.py", line 112, in clean_disease_data
    df = pd.read_csv(input_csv_path)
         ^^^^^^^^^^^^^^^^^^^^^^^^^^^
  File "C:\Users\Admin\AppData\Local\Packages\PythonSoftwareFoundation.Python.3.11_qbz5n2kfra8p0\LocalCache\local-packages\Python311\site-packages\pandas\io\parsers\readers.py", line 1026, in read_csv
    return _read(filepath_or_buffer, kwds)
           ^^^^^^^^^^^^^^^^^^^^^^^^^^^^^^^
  File "C:\Users\Admin\AppData\Local\Packages\PythonSoftwareFoundation.Python.3.11_qbz5n2kfra8p0\LocalCache\local-packages\Python311\site-packages\pandas\io\parsers\readers.py", line 626, in _read
    return parser.read(nrows)
           ^^^^^^^^^^^^^^^^^^
  File "C:\Users\Admin\AppData\Local\Packages\PythonSoftwareFoundation.Python.3.11_qbz5n2kfra8p0\LocalCache\local-packages\Python311\site-packages\pandas\io\parsers\readers.py", line 1923, in read
    ) = self._engine.read(  # type: ignore[attr-defined]
        ^^^^^^^^^^^^^^^^^^^^^^^^^^^^^^^^^^^^^^^^^^^^^^^^
  File "C:\Users\Admin\AppData\Local\Packages\PythonSoftwareFoundation.Python.3.11_qbz5n2kfra8p0\LocalCache\local-packages\Python311\site-packages\pandas\io\parsers\c_parser_wrapper.py", line 234, in read
    chunks = self._reader.read_low_memory(nrows)
             ^^^^^^^^^^^^^^^^^^^^^^^^^^^^^^^^^^^
  File "pandas/_libs/parsers.pyx", line 838, in pandas._libs.parsers.TextReader.read_low_memory
  File "pandas/_libs/parsers.pyx", line 905, in pandas._libs.parsers.TextReader._read_rows
  File "pandas/_libs/parsers.pyx", line 874, in pandas._libs.parsers.TextReader._tokenize_rows
  File "pandas/_libs/parsers.pyx", line 891, in pandas._libs.parsers.TextReader._check_tokenize_status
  File "pandas/_libs/parsers.pyx", line 2061, in pandas._libs.parsers.raise_parser_error
pandas.errors.ParserError: Error tokenizing data. C error: Expected 3 fields in line 66, saw 5

2025-08-05 20:51:10,137 - logic - ERROR - Failed to clean data. Cannot proceed with loading resources.
2025-08-05 20:51:10,137 - app - ERROR - Failed to initialize SymptomChecker: Failed to initialize SymptomChecker resources. Please check logs.
2025-08-05 20:54:41,438 - logic - INFO - Attempting to load symptom checker resources...
2025-08-05 20:54:41,438 - logic - WARNING - Cleaned data file 'data/cleaned_diseases.csv' not found. Attempting to clean original data from 'data/diseases.csv'.
2025-08-05 20:54:41,439 - data_utils - INFO - Starting advanced data cleaning from 'data/diseases.csv' to 'data/cleaned_diseases.csv'...
2025-08-05 20:54:41,450 - data_utils - ERROR - An error occurred during advanced data cleaning: Error tokenizing data. C error: Expected 3 fields in line 118, saw 8
Traceback (most recent call last):
  File "C:\Users\Admin\Documents\GitHub\idk-wut\data_utils.py", line 112, in clean_disease_data
    df = pd.read_csv(input_csv_path)
         ^^^^^^^^^^^^^^^^^^^^^^^^^^^
  File "C:\Users\Admin\AppData\Local\Packages\PythonSoftwareFoundation.Python.3.11_qbz5n2kfra8p0\LocalCache\local-packages\Python311\site-packages\pandas\io\parsers\readers.py", line 1026, in read_csv
    return _read(filepath_or_buffer, kwds)
           ^^^^^^^^^^^^^^^^^^^^^^^^^^^^^^^
  File "C:\Users\Admin\AppData\Local\Packages\PythonSoftwareFoundation.Python.3.11_qbz5n2kfra8p0\LocalCache\local-packages\Python311\site-packages\pandas\io\parsers\readers.py", line 626, in _read
    return parser.read(nrows)
           ^^^^^^^^^^^^^^^^^^
  File "C:\Users\Admin\AppData\Local\Packages\PythonSoftwareFoundation.Python.3.11_qbz5n2kfra8p0\LocalCache\local-packages\Python311\site-packages\pandas\io\parsers\readers.py", line 1923, in read
    ) = self._engine.read(  # type: ignore[attr-defined]
        ^^^^^^^^^^^^^^^^^^^^^^^^^^^^^^^^^^^^^^^^^^^^^^^^
  File "C:\Users\Admin\AppData\Local\Packages\PythonSoftwareFoundation.Python.3.11_qbz5n2kfra8p0\LocalCache\local-packages\Python311\site-packages\pandas\io\parsers\c_parser_wrapper.py", line 234, in read
    chunks = self._reader.read_low_memory(nrows)
             ^^^^^^^^^^^^^^^^^^^^^^^^^^^^^^^^^^^
  File "pandas/_libs/parsers.pyx", line 838, in pandas._libs.parsers.TextReader.read_low_memory
  File "pandas/_libs/parsers.pyx", line 905, in pandas._libs.parsers.TextReader._read_rows
  File "pandas/_libs/parsers.pyx", line 874, in pandas._libs.parsers.TextReader._tokenize_rows
  File "pandas/_libs/parsers.pyx", line 891, in pandas._libs.parsers.TextReader._check_tokenize_status
  File "pandas/_libs/parsers.pyx", line 2061, in pandas._libs.parsers.raise_parser_error
pandas.errors.ParserError: Error tokenizing data. C error: Expected 3 fields in line 118, saw 8

2025-08-05 20:54:41,453 - logic - ERROR - Failed to clean data. Cannot proceed with loading resources.
2025-08-05 20:54:41,453 - app - ERROR - Failed to initialize SymptomChecker: Failed to initialize SymptomChecker resources. Please check logs.
2025-08-05 20:54:42,960 - werkzeug - INFO - [31m[1mWARNING: This is a development server. Do not use it in a production deployment. Use a production WSGI server instead.[0m
 * Running on all addresses (0.0.0.0)
 * Running on http://127.0.0.1:5000
 * Running on http://198.18.0.1:5000
2025-08-05 20:54:42,960 - werkzeug - INFO - [33mPress CTRL+C to quit[0m
2025-08-05 20:54:43,038 - werkzeug - INFO -  * Restarting with watchdog (windowsapi)
2025-08-05 20:54:54,422 - logic - INFO - Attempting to load symptom checker resources...
2025-08-05 20:54:54,422 - logic - WARNING - Cleaned data file 'data/cleaned_diseases.csv' not found. Attempting to clean original data from 'data/diseases.csv'.
2025-08-05 20:54:54,422 - data_utils - INFO - Starting advanced data cleaning from 'data/diseases.csv' to 'data/cleaned_diseases.csv'...
2025-08-05 20:54:54,425 - data_utils - ERROR - An error occurred during advanced data cleaning: Error tokenizing data. C error: Expected 3 fields in line 118, saw 8
Traceback (most recent call last):
  File "C:\Users\Admin\Documents\GitHub\idk-wut\data_utils.py", line 112, in clean_disease_data
    df = pd.read_csv(input_csv_path)
         ^^^^^^^^^^^^^^^^^^^^^^^^^^^
  File "C:\Users\Admin\AppData\Local\Packages\PythonSoftwareFoundation.Python.3.11_qbz5n2kfra8p0\LocalCache\local-packages\Python311\site-packages\pandas\io\parsers\readers.py", line 1026, in read_csv
    return _read(filepath_or_buffer, kwds)
           ^^^^^^^^^^^^^^^^^^^^^^^^^^^^^^^
  File "C:\Users\Admin\AppData\Local\Packages\PythonSoftwareFoundation.Python.3.11_qbz5n2kfra8p0\LocalCache\local-packages\Python311\site-packages\pandas\io\parsers\readers.py", line 626, in _read
    return parser.read(nrows)
           ^^^^^^^^^^^^^^^^^^
  File "C:\Users\Admin\AppData\Local\Packages\PythonSoftwareFoundation.Python.3.11_qbz5n2kfra8p0\LocalCache\local-packages\Python311\site-packages\pandas\io\parsers\readers.py", line 1923, in read
    ) = self._engine.read(  # type: ignore[attr-defined]
        ^^^^^^^^^^^^^^^^^^^^^^^^^^^^^^^^^^^^^^^^^^^^^^^^
  File "C:\Users\Admin\AppData\Local\Packages\PythonSoftwareFoundation.Python.3.11_qbz5n2kfra8p0\LocalCache\local-packages\Python311\site-packages\pandas\io\parsers\c_parser_wrapper.py", line 234, in read
    chunks = self._reader.read_low_memory(nrows)
             ^^^^^^^^^^^^^^^^^^^^^^^^^^^^^^^^^^^
  File "pandas/_libs/parsers.pyx", line 838, in pandas._libs.parsers.TextReader.read_low_memory
  File "pandas/_libs/parsers.pyx", line 905, in pandas._libs.parsers.TextReader._read_rows
  File "pandas/_libs/parsers.pyx", line 874, in pandas._libs.parsers.TextReader._tokenize_rows
  File "pandas/_libs/parsers.pyx", line 891, in pandas._libs.parsers.TextReader._check_tokenize_status
  File "pandas/_libs/parsers.pyx", line 2061, in pandas._libs.parsers.raise_parser_error
pandas.errors.ParserError: Error tokenizing data. C error: Expected 3 fields in line 118, saw 8

2025-08-05 20:54:54,428 - logic - ERROR - Failed to clean data. Cannot proceed with loading resources.
2025-08-05 20:54:54,429 - app - ERROR - Failed to initialize SymptomChecker: Failed to initialize SymptomChecker resources. Please check logs.
2025-08-05 20:54:54,444 - werkzeug - WARNING -  * Debugger is active!
2025-08-05 20:54:54,460 - werkzeug - INFO -  * Debugger PIN: 736-584-036
2025-08-05 20:55:55,181 - werkzeug - INFO - 127.0.0.1 - - [05/Aug/2025 20:55:55] "GET / HTTP/1.1" 200 -
2025-08-05 20:55:55,181 - werkzeug - INFO -  * Detected change in 'C:\\Program Files\\WindowsApps\\PythonSoftwareFoundation.Python.3.11_3.11.2544.0_x64__qbz5n2kfra8p0\\Lib\\encodings\\unicode_escape.py', reloading
2025-08-05 20:55:55,466 - werkzeug - INFO - 127.0.0.1 - - [05/Aug/2025 20:55:55] "GET /static/css/style.css HTTP/1.1" 200 -
2025-08-05 20:55:55,516 - werkzeug - INFO - 127.0.0.1 - - [05/Aug/2025 20:55:55] "GET /static/js/main.js HTTP/1.1" 200 -
2025-08-05 20:55:55,596 - app - WARNING - 404 Error: Requested path '/favicon.ico' not found.
2025-08-05 20:55:55,597 - werkzeug - INFO - 127.0.0.1 - - [05/Aug/2025 20:55:55] "[33mGET /favicon.ico HTTP/1.1[0m" 404 -
2025-08-05 20:55:57,185 - werkzeug - INFO -  * Restarting with watchdog (windowsapi)
2025-08-05 20:56:08,690 - logic - INFO - Attempting to load symptom checker resources...
2025-08-05 20:56:08,690 - logic - WARNING - Cleaned data file 'data/cleaned_diseases.csv' not found. Attempting to clean original data from 'data/diseases.csv'.
2025-08-05 20:56:08,690 - data_utils - INFO - Starting advanced data cleaning from 'data/diseases.csv' to 'data/cleaned_diseases.csv'...
2025-08-05 20:56:08,695 - data_utils - ERROR - An error occurred during advanced data cleaning: Error tokenizing data. C error: Expected 3 fields in line 118, saw 8
Traceback (most recent call last):
  File "C:\Users\Admin\Documents\GitHub\idk-wut\data_utils.py", line 112, in clean_disease_data
    df = pd.read_csv(input_csv_path)
         ^^^^^^^^^^^^^^^^^^^^^^^^^^^
  File "C:\Users\Admin\AppData\Local\Packages\PythonSoftwareFoundation.Python.3.11_qbz5n2kfra8p0\LocalCache\local-packages\Python311\site-packages\pandas\io\parsers\readers.py", line 1026, in read_csv
    return _read(filepath_or_buffer, kwds)
           ^^^^^^^^^^^^^^^^^^^^^^^^^^^^^^^
  File "C:\Users\Admin\AppData\Local\Packages\PythonSoftwareFoundation.Python.3.11_qbz5n2kfra8p0\LocalCache\local-packages\Python311\site-packages\pandas\io\parsers\readers.py", line 626, in _read
    return parser.read(nrows)
           ^^^^^^^^^^^^^^^^^^
  File "C:\Users\Admin\AppData\Local\Packages\PythonSoftwareFoundation.Python.3.11_qbz5n2kfra8p0\LocalCache\local-packages\Python311\site-packages\pandas\io\parsers\readers.py", line 1923, in read
    ) = self._engine.read(  # type: ignore[attr-defined]
        ^^^^^^^^^^^^^^^^^^^^^^^^^^^^^^^^^^^^^^^^^^^^^^^^
  File "C:\Users\Admin\AppData\Local\Packages\PythonSoftwareFoundation.Python.3.11_qbz5n2kfra8p0\LocalCache\local-packages\Python311\site-packages\pandas\io\parsers\c_parser_wrapper.py", line 234, in read
    chunks = self._reader.read_low_memory(nrows)
             ^^^^^^^^^^^^^^^^^^^^^^^^^^^^^^^^^^^
  File "pandas/_libs/parsers.pyx", line 838, in pandas._libs.parsers.TextReader.read_low_memory
  File "pandas/_libs/parsers.pyx", line 905, in pandas._libs.parsers.TextReader._read_rows
  File "pandas/_libs/parsers.pyx", line 874, in pandas._libs.parsers.TextReader._tokenize_rows
  File "pandas/_libs/parsers.pyx", line 891, in pandas._libs.parsers.TextReader._check_tokenize_status
  File "pandas/_libs/parsers.pyx", line 2061, in pandas._libs.parsers.raise_parser_error
pandas.errors.ParserError: Error tokenizing data. C error: Expected 3 fields in line 118, saw 8

2025-08-05 20:56:08,698 - logic - ERROR - Failed to clean data. Cannot proceed with loading resources.
2025-08-05 20:56:08,698 - app - ERROR - Failed to initialize SymptomChecker: Failed to initialize SymptomChecker resources. Please check logs.
2025-08-05 20:56:08,713 - werkzeug - WARNING -  * Debugger is active!
2025-08-05 20:56:08,729 - werkzeug - INFO -  * Debugger PIN: 736-584-036
2025-08-05 20:56:17,824 - werkzeug - INFO - 127.0.0.1 - - [05/Aug/2025 20:56:17] "[32mPOST / HTTP/1.1[0m" 302 -
2025-08-05 20:56:18,093 - werkzeug - INFO - 127.0.0.1 - - [05/Aug/2025 20:56:18] "GET / HTTP/1.1" 200 -
2025-08-05 20:56:18,196 - werkzeug - INFO - 127.0.0.1 - - [05/Aug/2025 20:56:18] "[36mGET /static/css/style.css HTTP/1.1[0m" 304 -
2025-08-05 20:56:18,428 - werkzeug - INFO - 127.0.0.1 - - [05/Aug/2025 20:56:18] "[36mGET /static/js/main.js HTTP/1.1[0m" 304 -
2025-08-05 20:56:24,937 - werkzeug - INFO - 127.0.0.1 - - [05/Aug/2025 20:56:24] "[32mPOST / HTTP/1.1[0m" 302 -
2025-08-05 20:56:25,244 - werkzeug - INFO - 127.0.0.1 - - [05/Aug/2025 20:56:25] "GET / HTTP/1.1" 200 -
2025-08-05 20:56:25,508 - werkzeug - INFO - 127.0.0.1 - - [05/Aug/2025 20:56:25] "[36mGET /static/css/style.css HTTP/1.1[0m" 304 -
2025-08-05 20:56:25,573 - werkzeug - INFO - 127.0.0.1 - - [05/Aug/2025 20:56:25] "[36mGET /static/js/main.js HTTP/1.1[0m" 304 -
2025-08-05 20:56:30,117 - werkzeug - INFO - 127.0.0.1 - - [05/Aug/2025 20:56:30] "[36mGET /static/css/style.css HTTP/1.1[0m" 304 -
2025-08-05 20:56:30,431 - app - WARNING - 404 Error: Requested path '/.well-known/appspecific/com.chrome.devtools.json' not found.
2025-08-05 20:56:30,434 - werkzeug - INFO - 127.0.0.1 - - [05/Aug/2025 20:56:30] "[33mGET /.well-known/appspecific/com.chrome.devtools.json HTTP/1.1[0m" 404 -
